Workbook

Sheet Posts
A1: Post ID | B1: Platform | C1: Date | D1: Content Type | E1: Post Text | F1: Likes | G1: Shares | H1: Comments | I1: Impressions | J1: Reach | K1: Clicks | L1: Engagement | M1: Hashtags Used | N1: Hashtag 1 | O1: Hashtag 2 | P1: Hashtag 3 | Q1: Campaign_Name | R1: Engagement_Rate
A2: P001 | B2: Twitter | C2: 45649 | D2: Reel | E2: Check out our latest reel on twitter! | F2: 1461 | G2: 184 | H2: 344 | I2: 21915 | J2: 21675 | K2: 15 | L2: =SUM($F2:$H2) -> 1989 | M2: #LiveForNow,#AnytimeIsPepsiTime | N2: #LiveForNow | O2: #AnytimeIsPepsiTime | Q2: SummerSplash | R2: =SUM(F2:H2)/I2 -> 0.090759754
A3: P002 | B3: Twitter | C3: 45750 | D3: Text | E3: Check out our latest text on twitter! | F3: 4054 | G3: 389 | H3: 493 | I3: 64864 | J3: 64383 | K3: 117 | L3: =SUM($F3:$H3) -> 4936 | M3: #PepsiCoRefresh,#BetterWithPepsi | N3: #PepsiCoRefresh | O3: #BetterWithPepsi | Q3: FestiveRadiance | R3: =SUM(F3:H3)/I3 -> 0.076097681
A4: P003 | B4: YouTube | C4: 45789 | D4: Reel | E4: Check out our latest reel on youtube! | F4: 2795 | G4: 105 | H4: 49 | I4: 53105 | J4: 52307 | K4: 204 | L4: =SUM($F4:$H4) -> 2949 | M4: #PepsiCoRefresh | N4: #PepsiCoRefresh | Q4: NewYearRefresh | R4: =SUM(F4:H4)/I4 -> 0.055531494
A5: P004 | B5: Instagram | C5: 45516 | D5: Story | E5: Check out our latest story on instagram! | F5: 2404 | G5: 363 | H5: 138 | I5: 19232 | J5: 18636 | K5: 128 | L5: =SUM($F5:$H5) -> 2905 | M5: #ThirstyForMore | N5: #ThirstyForMore | Q5: DailyWellness | R5: =SUM(F5:H5)/I5 -> 0.15105033
A6: P005 | B6: YouTube | C6: 45469 | D6: Reel | E6: Check out our latest reel on youtube! | F6: 3557 | G6: 687 | H6: 424 | I6: 71140 | J6: 70701 | K6: 224 | L6: =SUM($F6:$H6) -> 4668 | M6: #ThirstyForMore,#PepsiCoRefresh | N6: #ThirstyForMore | O6: #PepsiCoRefresh | Q6: SummerSplash | R6: =SUM(F6:H6)/I6 -> 0.065617093
A7: P006 | B7: Facebook | C7: 45596 | D7: Carousel | E7: Check out our latest carousel on facebook! | F7: 2945 | G7: 930 | H7: 355 | I7: 23560 | J7: 23275 | K7: 256 | L7: =SUM($F7:$H7) -> 4230 | M7: #PepsiCoRefresh | N7: #PepsiCoRefresh | Q7: FestiveRadiance | R7: =SUM(F7:H7)/I7 -> 0.1795416
A8: P007 | B8: Twitter | C8: 45467 | D8: Carousel | E8: Check out our latest carousel on twitter! | F8: 3860 | G8: 201 | H8: 279 | I8: 61760 | J8: 61660 | K8: 235 | L8: =SUM($F8:$H8) -> 4340 | M8: #PepsiCoRefresh | N8: #PepsiCoRefresh | Q8: FestiveRadiance | R8: =SUM(F8:H8)/I8 -> 0.070272021
A9: P008 | B9: YouTube | C9: 45486 | D9: Image | E9: Check out our latest image on youtube! | F9: 3929 | G9: 262 | H9: 278 | I9: 43219 | J9: 42841 | K9: 39 | L9: =SUM($F9:$H9) -> 4469 | M9: #ThirstyForMore | N9: #ThirstyForMore | Q9: DailyWellness | R9: =SUM(F9:H9)/I9 -> 0.1034036
A10: P009 | B10: Facebook | C10: 45534 | D10: Text | E10: Check out our latest text on facebook! | F10: 3784 | G10: 808 | H10: 404 | I10: 56760 | J10: 56343 | K10: 131 | L10: =SUM($F10:$H10) -> 4996 | M10: #PepsiCoRefresh | N10: #PepsiCoRefresh | Q10: FestiveRadiance | R10: =SUM(F10:H10)/I10 -> 0.088019732
A11: P010 | B11: Facebook | C11: 45727 | D11: Image | E11: Check out our latest image on facebook! | F11: 4241 | G11: 902 | H11: 47 | I11: 72097 | J11: 71598 | K11: 167 | L11: =SUM($F11:$H11) -> 5190 | M11: #PepsiCoRefresh | N11: #PepsiCoRefresh | Q11: FestiveRadiance | R11: =SUM(F11:H11)/I11 -> 0.071986352
A12: P011 | B12: Instagram | C12: 45690 | D12: Story | E12: Check out our latest story on instagram! | F12: 1792 | G12: 614 | H12: 497 | I12: 25088 | J12: 24675 | K12: 65 | L12: =SUM($F12:$H12) -> 2903 | M12: #LiveForNow | N12: #LiveForNow | Q12: DailyWellness | R12: =SUM(F12:H12)/I12 -> 0.11571269
A13: P012 | B13: Facebook | C13: 45494 | D13: Reel | E13: Check out our latest reel on facebook! | F13: 1946 | G13: 686 | H13: 377 | I13: 23352 | J13: 22982 | K13: 213 | L13: =SUM($F13:$H13) -> 3009 | M13: #LiveForNow | N13: #LiveForNow | Q13: NewYearRefresh | R13: =SUM(F13:H13)/I13 -> 0.12885406
A14: P013 | B14: YouTube | C14: 45614 | D14: Carousel | E14: Check out our latest carousel on youtube! | F14: 1171 | G14: 286 | H14: 231 | I14: 22249 | J14: 21282 | K14: 114 | L14: =SUM($F14:$H14) -> 1688 | M14: #ThirstyForMore | N14: #ThirstyForMore | Q14: SummerSplash | R14: =SUM(F14:H14)/I14 -> 0.075868578
A15: P014 | B15: Facebook | C15: 45704 | D15: Story | E15: Check out our latest story on facebook! | F15: 4242 | G15: 555 | H15: 131 | I15: 33936 | J15: 33802 | K15: 265 | L15: =SUM($F15:$H15) -> 4928 | M15: #LiveForNow | N15: #LiveForNow | Q15: Unassigned | R15: =SUM(F15:H15)/I15 -> 0.14521452
A16: P015 | B16: Facebook | C16: 45589 | D16: Video | E16: Check out our latest video on facebook! | F16: 3888 | G16: 604 | H16: 128 | I16: 77760 | J16: 77167 | K16: 20 | L16: =SUM($F16:$H16) -> 4620 | M16: #LiveForNow | N16: #LiveForNow | Q16: SummerSplash | R16: =SUM(F16:H16)/I16 -> 0.05941358
A17: P016 | B17: Facebook | C17: 45530 | D17: Text | E17: Check out our latest text on facebook! | F17: 3452 | G17: 377 | H17: 360 | I17: 55232 | J17: 55075 | K17: 87 | L17: =SUM($F17:$H17) -> 4189 | M17: #LiveForNow | N17: #LiveForNow | Q17: NewYearRefresh | R17: =SUM(F17:H17)/I17 -> 0.075843714
A18: P017 | B18: Facebook | C18: 45782 | D18: Text | E18: Check out our latest text on facebook! | F18: 4441 | G18: 511 | H18: 70 | I18: 53292 | J18: 53082 | K18: 159 | L18: =SUM($F18:$H18) -> 5022 | M18: #ThirstyForMore | N18: #ThirstyForMore | Q18: DailyWellness | R18: =SUM(F18:H18)/I18 -> 0.094235533
... A23: P022 | B23: Facebook | C23: 45715 | D23: Text | E23: Check out our latest text on facebook! | F23: 1570 | G23: 187 | H23: 260 | I23: 25120 | J23: 24613 | K23: 133 | L23: =SUM($F23:$H23) -> 2017 | M23: #PepsiCoRefresh | N23: #PepsiCoRefresh | Q23: DailyWellness | R23: =SUM(F23:H23)/I23 -> 0.080294586
A24: P023 | B24: Facebook | C24: 45602 | D24: Video | E24: Check out our latest video on facebook! | F24: 1606 | G24: 547 | H24: 316 | I24: 32120 | J24: 31736 | K24: 225 | L24: =SUM($F24:$H24) -> 2469 | M24: #PepsiCoRefresh,#AnytimeIsPepsiTime | N24: #PepsiCoRefresh | O24: #AnytimeIsPepsiTime | Q24: FestiveRadiance | R24: =SUM(F24:H24)/I24 -> 0.076867995
A25: P024 | B25: Facebook | C25: 45680 | D25: Video | E25: Check out our latest video on facebook! | F25: 3961 | G25: 761 | H25: 131 | I25: 67337 | J25: 66615 | K25: 161 | L25: =SUM($F25:$H25) -> 4853 | M25: #LiveForNow | N25: #LiveForNow | Q25: NewYearRefresh | R25: =SUM(F25:H25)/I25 -> 0.072070333
A26: P025 | B26: Twitter | C26: 45757 | D26: Carousel | E26: Check out our latest carousel on twitter! | F26: 3128 | G26: 211 | H26: 197 | I26: 59432 | J26: 59182 | K26: 238 | L26: =SUM($F26:$H26) -> 3536 | M26: #ThirstyForMore | N26: #ThirstyForMore | Q26: Unassigned | R26: =SUM(F26:H26)/I26 -> 0.059496568
A27: P026 | B27: YouTube | C27: 45752 | D27: Reel | E27: Check out our latest reel on youtube! | F27: 3009 | G27: 413 | H27: 358 | I27: 42126 | J27: 41309 | K27: 211 | L27: =SUM($F27:$H27) -> 3780 | M27: #LiveForNow | N27: #LiveForNow | Q27: FestiveRadiance | R27: =SUM(F27:H27)/I27 -> 0.089730808
A28: P027 | B28: YouTube | C28: 45552 | D28: Text | E28: Check out our latest text on youtube! | F28: 2076 | G28: 195 | H28: 104 | I28: 33216 | J28: 32244 | K28: 51 | L28: =SUM($F28:$H28) -> 2375 | M28: #LiveForNow | N28: #LiveForNow | Q28: DailyWellness | R28: =SUM(F28:H28)/I28 -> 0.071501686
A29: P028 | B29: Instagram | C29: 45720 | D29: Video | E29: Check out our latest video on instagram! | F29: 432 | G29: 624 | H29: 123 | I29: 6912 | J29: 6259 | K29: 79 | L29: =SUM($F29:$H29) -> 1179 | M29: #LiveForNow | N29: #LiveForNow | Q29: DailyWellness | R29: =SUM(F29:H29)/I29 -> 0.17057292
A30: P029 | B30: Instagram | C30: 45688 | D30: Carousel | E30: Check out our latest carousel on instagram! | F30: 2566 | G30: 118 | H30: 37 | I30: 12830 | J30: 12264 | K30: 221 | L30: =SUM($F30:$H30) -> 2721 | M30: #LiveForNow | N30: #LiveForNow | Q30: NewYearRefresh | R30: =SUM(F30:H30)/I30 -> 0.21208106
A31: P030 | B31: Instagram | C31: 45713 | D31: Video | E31: Check out our latest video on instagram! | F31: 3095 | G31: 39 | H31: 78 | I31: 55710 | J31: 54808 | K31: 93 | L31: =SUM($F31:$H31) -> 3212 | M31: #ThirstyForMore | N31: #ThirstyForMore | Q31: Unassigned | R31: =SUM(F31:H31)/I31 -> 0.057655717
A32: P031 | B32: Instagram | C32: 45642 | D32: Text | E32: Check out our latest text on instagram! | F32: 438 | G32: 153 | H32: 275 | I32: 3066 | J32: 2701 | K32: 282 | L32: =SUM($F32:$H32) -> 866 | M32: #PepsiCoRefresh | N32: #PepsiCoRefresh | Q32: FestiveRadiance | R32: =SUM(F32:H32)/I32 -> 0.28245271
A33: P032 | B33: Twitter | C33: 45504 | D33: Carousel | E33: Check out our latest carousel on twitter! | F33: 2278 | G33: 10 | H33: 321 | I33: 13668 | J33: 12676 | K33: 275 | L33: =SUM($F33:$H33) -> 2609 | M33: #ThirstyForMore | N33: #ThirstyForMore | Q33: SummerSplash | R33: =SUM(F33:H33)/I33 -> 0.19088382
A34: P033 | B34: Facebook | C34: 45525 | D34: Image | E34: Check out our latest image on facebook! | F34: 1407 | G34: 400 | H34: 351 | I34: 16884 | J34: 15954 | K34: 113 | L34: =SUM($F34:$H34) -> 2158 | M34: #PepsiCoRefresh | N34: #PepsiCoRefresh | Q34: SummerSplash | R34: =SUM(F34:H34)/I34 -> 0.12781331
A35: P034 | B35: Facebook | C35: 45742 | D35: Text | E35: Check out our latest text on facebook! | F35: 1652 | G35: 89 | H35: 357 | I35: 29736 | J35: 28771 | K35: 215 | L35: =SUM($F35:$H35) -> 2098 | M35: #PepsiCoRefresh | N35: #PepsiCoRefresh | Q35: NewYearRefresh | R35: =SUM(F35:H35)/I35 -> 0.07055421
A36: P035 | B36: Instagram | C36: 45626 | D36: Video | E36: Check out our latest video on instagram! | F36: 3775 | G36: 16 | H36: 239 | I36: 33975 | J36: 33310 | K36: 271 | L36: =SUM($F36:$H36) -> 4030 | M36: #LiveForNow | N36: #LiveForNow | Q36: FestiveRadiance | R36: =SUM(F36:H36)/I36 -> 0.11861663
... A53: P052 | B53: Facebook | C53: 45660 | D53: Image | E53: Check out our latest image on facebook! | F53: 947 | G53: 338 | H53: 350 | I53: 10417 | J53: 9730 | K53: 34 | L53: =SUM($F53:$H53) -> 1635 | M53: #PepsiCoRefresh | N53: #PepsiCoRefresh | Q53: DailyWellness | R53: =SUM(F53:H53)/I53 -> 0.15695498
A54: P053 | B54: YouTube | C54: 45712 | D54: Carousel | E54: Check out our latest carousel on youtube! | F54: 804 | G54: 639 | H54: 43 | I54: 4020 | J54: 3144 | K54: 11 | L54: =SUM($F54:$H54) -> 1486 | M54: #ThirstyForMore,#BetterWithPepsi | N54: #ThirstyForMore | O54: #BetterWithPepsi | Q54: Unassigned | R54: =SUM(F54:H54)/I54 -> 0.36965174
A55: P054 | B55: YouTube | C55: 45729 | D55: Carousel | E55: Check out our latest carousel on youtube! | F55: 1686 | G55: 904 | H55: 472 | I55: 18546 | J55: 18171 | K55: 52 | L55: =SUM($F55:$H55) -> 3062 | M55: #LiveForNow | N55: #LiveForNow | Q55: FestiveRadiance | R55: =SUM(F55:H55)/I55 -> 0.16510299
A56: P055 | B56: Facebook | C56: 45460 | D56: Image | E56: Check out our latest image on facebook! | F56: 1226 | G56: 119 | H56: 7 | I56: 14712 | J56: 14049 | K56: 123 | L56: =SUM($F56:$H56) -> 1352 | M56: #ThirstyForMore | N56: #ThirstyForMore | Q56: DailyWellness | R56: =SUM(F56:H56)/I56 -> 0.091897771
A57: P056 | B57: Facebook | C57: 45644 | D57: Carousel | E57: Check out our latest carousel on facebook! | F57: 2946 | G57: 498 | H57: 367 | I57: 29460 | J57: 28527 | K57: 60 | L57: =SUM($F57:$H57) -> 3811 | M57: #LiveForNow | N57: #LiveForNow | Q57: NewYearRefresh | R57: =SUM(F57:H57)/I57 -> 0.12936185
A58: P057 | B58: Twitter | C58: 45586 | D58: Video | E58: Check out our latest video on twitter! | F58: 2825 | G58: 535 | H58: 295 | I58: 45200 | J58: 44739 | K58: 169 | L58: =SUM($F58:$H58) -> 3655 | M58: #PepsiCoRefresh | N58: #PepsiCoRefresh | Q58: SummerSplash | R58: =SUM(F58:H58)/I58 -> 0.080862832
A59: P058 | B59: Instagram | C59: 45762 | D59: Reel | E59: Check out our latest reel on instagram! | F59: 103 | G59: 770 | H59: 19 | I59: 1030 | J59: 410 | K59: 262 | L59: =SUM($F59:$H59) -> 892 | M59: #PepsiCoRefresh | N59: #PepsiCoRefresh | Q59: DailyWellness | R59: =SUM(F59:H59)/I59 -> 0.86601942
A60: P059 | B60: Instagram | C60: 45465 | D60: Text | E60: Check out our latest text on instagram! | F60: 2180 | G60: 263 | H60: 387 | I60: 30520 | J60: 30059 | K60: 174 | L60: =SUM($F60:$H60) -> 2830 | M60: #ThirstyForMore | N60: #ThirstyForMore | Q60: Unassigned | R60: =SUM(F60:H60)/I60 -> 0.092726081
...

Sheet Table 2
A1: Post ID | B1: Platform | C1: Date | D1: Content Type | E1: Post Text | F1: Likes | G1: Shares | H1: Comments | I1: Impressions | J1: Reach | K1: Clicks | L1: Engagement | M1: Hashtags Used | N1: Hashtag 1 | O1: Hashtag 2 | P1: Hashtag 3 | Q1: Campaign_Name | R1: Engagement_Rate
A2: P001 | B2: Twitter | C2: 45649 | D2: Reel | E2: Check out our latest reel on twitter! | F2: 1461 | G2: 184 | H2: 344 | I2: 21915 | J2: 21675 | K2: 15 | L2: =SUM($F2:$H2) -> 1989 | M2: #LiveForNow,#AnytimeIsPepsiTime | N2: #LiveForNow | O2: #AnytimeIsPepsiTime | Q2: SummerSplash | R2: =SUM(F2:H2)/I2 -> 0.090759754
A3: P002 | B3: Twitter | C3: 45750 | D3: Text | E3: Check out our latest text on twitter! | F3: 4054 | G3: 389 | H3: 493 | I3: 64864 | J3: 64383 | K3: 117 | L3: =SUM($F3:$H3) -> 4936 | M3: #PepsiCoRefresh,#BetterWithPepsi | N3: #PepsiCoRefresh | O3: #BetterWithPepsi | Q3: FestiveRadiance | R3: =SUM(F3:H3)/I3 -> 0.076097681
A4: P003 | B4: YouTube | C4: 45789 | D4: Reel | E4: Check out our latest reel on youtube! | F4: 2795 | G4: 105 | H4: 49 | I4: 53105 | J4: 52307 | K4: 204 | L4: =SUM($F4:$H4) -> 2949 | M4: #PepsiCoRefresh | N4: #PepsiCoRefresh | Q4: NewYearRefresh | R4: =SUM(F4:H4)/I4 -> 0.055531494
A5: P004 | B5: Instagram | C5: 45516 | D5: Story | E5: Check out our latest story on instagram! | F5: 2404 | G5: 363 | H5: 138 | I5: 19232 | J5: 18636 | K5: 128 | L5: =SUM($F5:$H5) -> 2905 | M5: #ThirstyForMore | N5: #ThirstyForMore | Q5: DailyWellness | R5: =SUM(F5:H5)/I5 -> 0.15105033
A6: P005 | B6: YouTube | C6: 45469 | D6: Reel | E6: Check out our latest reel on youtube! | F6: 3557 | G6: 687 | H6: 424 | I6: 71140 | J6: 70701 | K6: 224 | L6: =SUM($F6:$H6) -> 4668 | M6: #ThirstyForMore,#PepsiCoRefresh | N6: #ThirstyForMore | O6: #PepsiCoRefresh | Q6: SummerSplash | R6: =SUM(F6:H6)/I6 -> 0.065617093
A7: P006 | B7: Facebook | C7: 45596 | D7: Carousel | E7: Check out our latest carousel on facebook! | F7: 2945 | G7: 930 | H7: 355 | I7: 23560 | J7: 23275 | K7: 256 | L7: =SUM($F7:$H7) -> 4230 | M7: #PepsiCoRefresh | N7: #PepsiCoRefresh | Q7: FestiveRadiance | R7: =SUM(F7:H7)/I7 -> 0.1795416
A8: P007 | B8: Twitter | C8: 45467 | D8: Carousel | E8: Check out our latest carousel on twitter! | F8: 3860 | G8: 201 | H8: 279 | I8: 61760 | J8: 61660 | K8: 235 | L8: =SUM($F8:$H8) -> 4340 | M8: #PepsiCoRefresh | N8: #PepsiCoRefresh | Q8: FestiveRadiance | R8: =SUM(F8:H8)/I8 -> 0.070272021
A9: P008 | B9: YouTube | C9: 45486 | D9: Image | E9: Check out our latest image on youtube! | F9: 3929 | G9: 262 | H9: 278 | I9: 43219 | J9: 42841 | K9: 39 | L9: =SUM($F9:$H9) -> 4469 | M9: #ThirstyForMore | N9: #ThirstyForMore | Q9: DailyWellness | R9: =SUM(F9:H9)/I9 -> 0.1034036
A10: P009 | B10: Facebook | C10: 45534 | D10: Text | E10: Check out our latest text on facebook! | F10: 3784 | G10: 808 | H10: 404 | I10: 56760 | J10: 56343 | K10: 131 | L10: =SUM($F10:$H10) -> 4996 | M10: #PepsiCoRefresh | N10: #PepsiCoRefresh | Q10: FestiveRadiance | R10: =SUM(F10:H10)/I10 -> 0.088019732
A11: P010 | B11: Facebook | C11: 45727 | D11: Image | E11: Check out our latest image on facebook! | F11: 4241 | G11: 902 | H11: 47 | I11: 72097 | J11: 71598 | K11: 167 | L11: =SUM($F11:$H11) -> 5190 | M11: #PepsiCoRefresh | N11: #PepsiCoRefresh | Q11: FestiveRadiance | R11: =SUM(F11:H11)/I11 -> 0.071986352
A12: P011 | B12: Instagram | C12: 45690 | D12: Story | E12: Check out our latest story on instagram! | F12: 1792 | G12: 614 | H12: 497 | I12: 25088 | J12: 24675 | K12: 65 | L12: =SUM($F12:$H12) -> 2903 | M12: #LiveForNow | N12: #LiveForNow | Q12: DailyWellness | R12: =SUM(F12:H12)/I12 -> 0.11571269
A13: P012 | B13: Facebook | C13: 45494 | D13: Reel | E13: Check out our latest reel on facebook! | F13: 1946 | G13: 686 | H13: 377 | I13: 23352 | J13: 22982 | K13: 213 | L13: =SUM($F13:$H13) -> 3009 | M13: #LiveForNow | N13: #LiveForNow | Q13: NewYearRefresh | R13: =SUM(F13:H13)/I13 -> 0.12885406
A14: P013 | B14: YouTube | C14: 45614 | D14: Carousel | E14: Check out our latest carousel on youtube! | F14: 1171 | G14: 286 | H14: 231 | I14: 22249 | J14: 21282 | K14: 114 | L14: =SUM($F14:$H14) -> 1688 | M14: #ThirstyForMore | N14: #ThirstyForMore | Q14: SummerSplash | R14: =SUM(F14:H14)/I14 -> 0.075868578
A15: P014 | B15: Facebook | C15: 45704 | D15: Story | E15: Check out our latest story on facebook! | F15: 4242 | G15: 555 | H15: 131 | I15: 33936 | J15: 33802 | K15: 265 | L15: =SUM($F15:$H15) -> 4928 | M15: #LiveForNow | N15: #LiveForNow | Q15: Unassigned | R15: =SUM(F15:H15)/I15 -> 0.14521452
A16: P015 | B16: Facebook | C16: 45589 | D16: Video | E16: Check out our latest video on facebook! | F16: 3888 | G16: 604 | H16: 128 | I16: 77760 | J16: 77167 | K16: 20 | L16: =SUM($F16:$H16) -> 4620 | M16: #LiveForNow | N16: #LiveForNow | Q16: SummerSplash | R16: =SUM(F16:H16)/I16 -> 0.05941358
A17: P016 | B17: Facebook | C17: 45530 | D17: Text | E17: Check out our latest text on facebook! | F17: 3452 | G17: 377 | H17: 360 | I17: 55232 | J17: 55075 | K17: 87 | L17: =SUM($F17:$H17) -> 4189 | M17: #LiveForNow | N17: #LiveForNow | Q17: NewYearRefresh | R17: =SUM(F17:H17)/I17 -> 0.075843714
A18: P017 | B18: Facebook | C18: 45782 | D18: Text | E18: Check out our latest text on facebook! | F18: 4441 | G18: 511 | H18: 70 | I18: 53292 | J18: 53082 | K18: 159 | L18: =SUM($F18:$H18) -> 5022 | M18: #ThirstyForMore | N18: #ThirstyForMore | Q18: DailyWellness | R18: =SUM(F18:H18)/I18 -> 0.094235533
... A23: P022 | B23: Facebook | C23: 45715 | D23: Text | E23: Check out our latest text on facebook! | F23: 1570 | G23: 187 | H23: 260 | I23: 25120 | J23: 24613 | K23: 133 | L23: =SUM($F23:$H23) -> 2017 | M23: #PepsiCoRefresh | N23: #PepsiCoRefresh | Q23: DailyWellness | R23: =SUM(F23:H23)/I23 -> 0.080294586
A24: P023 | B24: Facebook | C24: 45602 | D24: Video | E24: Check out our latest video on facebook! | F24: 1606 | G24: 547 | H24: 316 | I24: 32120 | J24: 31736 | K24: 225 | L24: =SUM($F24:$H24) -> 2469 | M24: #PepsiCoRefresh,#AnytimeIsPepsiTime | N24: #PepsiCoRefresh | O24: #AnytimeIsPepsiTime | Q24: FestiveRadiance | R24: =SUM(F24:H24)/I24 -> 0.076867995
A25: P024 | B25: Facebook | C25: 45680 | D25: Video | E25: Check out our latest video on facebook! | F25: 3961 | G25: 761 | H25: 131 | I25: 67337 | J25: 66615 | K25: 161 | L25: =SUM($F25:$H25) -> 4853 | M25: #LiveForNow | N25: #LiveForNow | Q25: NewYearRefresh | R25: =SUM(F25:H25)/I25 -> 0.072070333
A26: P025 | B26: Twitter | C26: 45757 | D26: Carousel | E26: Check out our latest carousel on twitter! | F26: 3128 | G26: 211 | H26: 197 | I26: 59432 | J26: 59182 | K26: 238 | L26: =SUM($F26:$H26) -> 3536 | M26: #ThirstyForMore | N26: #ThirstyForMore | Q26: Unassigned | R26: =SUM(F26:H26)/I26 -> 0.059496568
A27: P026 | B27: YouTube | C27: 45752 | D27: Reel | E27: Check out our latest reel on youtube! | F27: 3009 | G27: 413 | H27: 358 | I27: 42126 | J27: 41309 | K27: 211 | L27: =SUM($F27:$H27) -> 3780 | M27: #LiveForNow | N27: #LiveForNow | Q27: FestiveRadiance | R27: =SUM(F27:H27)/I27 -> 0.089730808
A28: P027 | B28: YouTube | C28: 45552 | D28: Text | E28: Check out our latest text on youtube! | F28: 2076 | G28: 195 | H28: 104 | I28: 33216 | J28: 32244 | K28: 51 | L28: =SUM($F28:$H28) -> 2375 | M28: #LiveForNow | N28: #LiveForNow | Q28: DailyWellness | R28: =SUM(F28:H28)/I28 -> 0.071501686
A29: P028 | B29: Instagram | C29: 45720 | D29: Video | E29: Check out our latest video on instagram! | F29: 432 | G29: 624 | H29: 123 | I29: 6912 | J29: 6259 | K29: 79 | L29: =SUM($F29:$H29) -> 1179 | M29: #LiveForNow | N29: #LiveForNow | Q29: DailyWellness | R29: =SUM(F29:H29)/I29 -> 0.17057292
A30: P029 | B30: Instagram | C30: 45688 | D30: Carousel | E30: Check out our latest carousel on instagram! | F30: 2566 | G30: 118 | H30: 37 | I30: 12830 | J30: 12264 | K30: 221 | L30: =SUM($F30:$H30) -> 2721 | M30: #LiveForNow | N30: #LiveForNow | Q30: NewYearRefresh | R30: =SUM(F30:H30)/I30 -> 0.21208106
A31: P030 | B31: Instagram | C31: 45713 | D31: Video | E31: Check out our latest video on instagram! | F31: 3095 | G31: 39 | H31: 78 | I31: 55710 | J31: 54808 | K31: 93 | L31: =SUM($F31:$H31) -> 3212 | M31: #ThirstyForMore | N31: #ThirstyForMore | Q31: Unassigned | R31: =SUM(F31:H31)/I31 -> 0.057655717
A32: P031 | B32: Instagram | C32: 45642 | D32: Text | E32: Check out our latest text on instagram! | F32: 438 | G32: 153 | H32: 275 | I32: 3066 | J32: 2701 | K32: 282 | L32: =SUM($F32:$H32) -> 866 | M32: #PepsiCoRefresh | N32: #PepsiCoRefresh | Q32: FestiveRadiance | R32: =SUM(F32:H32)/I32 -> 0.28245271
A33: P032 | B33: Twitter | C33: 45504 | D33: Carousel | E33: Check out our latest carousel on twitter! | F33: 2278 | G33: 10 | H33: 321 | I33: 13668 | J33: 12676 | K33: 275 | L33: =SUM($F33:$H33) -> 2609 | M33: #ThirstyForMore | N33: #ThirstyForMore | Q33: SummerSplash | R33: =SUM(F33:H33)/I33 -> 0.19088382
A34: P033 | B34: Facebook | C34: 45525 | D34: Image | E34: Check out our latest image on facebook! | F34: 1407 | G34: 400 | H34: 351 | I34: 16884 | J34: 15954 | K34: 113 | L34: =SUM($F34:$H34) -> 2158 | M34: #PepsiCoRefresh | N34: #PepsiCoRefresh | Q34: SummerSplash | R34: =SUM(F34:H34)/I34 -> 0.12781331
A35: P034 | B35: Facebook | C35: 45742 | D35: Text | E35: Check out our latest text on facebook! | F35: 1652 | G35: 89 | H35: 357 | I35: 29736 | J35: 28771 | K35: 215 | L35: =SUM($F35:$H35) -> 2098 | M35: #PepsiCoRefresh | N35: #PepsiCoRefresh | Q35: NewYearRefresh | R35: =SUM(F35:H35)/I35 -> 0.07055421
A36: P035 | B36: Instagram | C36: 45626 | D36: Video | E36: Check out our latest video on instagram! | F36: 3775 | G36: 16 | H36: 239 | I36: 33975 | J36: 33310 | K36: 271 | L36: =SUM($F36:$H36) -> 4030 | M36: #LiveForNow | N36: #LiveForNow | Q36: FestiveRadiance | R36: =SUM(F36:H36)/I36 -> 0.11861663
... A53: P052 | B53: Facebook | C53: 45660 | D53: Image | E53: Check out our latest image on facebook! | F53: 947 | G53: 338 | H53: 350 | I53: 10417 | J53: 9730 | K53: 34 | L53: =SUM($F53:$H53) -> 1635 | M53: #PepsiCoRefresh | N53: #PepsiCoRefresh | Q53: DailyWellness | R53: =SUM(F53:H53)/I53 -> 0.15695498
A54: P053 | B54: YouTube | C54: 45712 | D54: Carousel | E54: Check out our latest carousel on youtube! | F54: 804 | G54: 639 | H54: 43 | I54: 4020 | J54: 3144 | K54: 11 | L54: =SUM($F54:$H54) -> 1486 | M54: #ThirstyForMore,#BetterWithPepsi | N54: #ThirstyForMore | O54: #BetterWithPepsi | Q54: Unassigned | R54: =SUM(F54:H54)/I54 -> 0.36965174
A55: P054 | B55: YouTube | C55: 45729 | D55: Carousel | E55: Check out our latest carousel on youtube! | F55: 1686 | G55: 904 | H55: 472 | I55: 18546 | J55: 18171 | K55: 52 | L55: =SUM($F55:$H55) -> 3062 | M55: #LiveForNow | N55: #LiveForNow | Q55: FestiveRadiance | R55: =SUM(F55:H55)/I55 -> 0.16510299
A56: P055 | B56: Facebook | C56: 45460 | D56: Image | E56: Check out our latest image on facebook! | F56: 1226 | G56: 119 | H56: 7 | I56: 14712 | J56: 14049 | K56: 123 | L56: =SUM($F56:$H56) -> 1352 | M56: #ThirstyForMore | N56: #ThirstyForMore | Q56: DailyWellness | R56: =SUM(F56:H56)/I56 -> 0.091897771
A57: P056 | B57: Facebook | C57: 45644 | D57: Carousel | E57: Check out our latest carousel on facebook! | F57: 2946 | G57: 498 | H57: 367 | I57: 29460 | J57: 28527 | K57: 60 | L57: =SUM($F57:$H57) -> 3811 | M57: #LiveForNow | N57: #LiveForNow | Q57: NewYearRefresh | R57: =SUM(F57:H57)/I57 -> 0.12936185
A58: P057 | B58: Twitter | C58: 45586 | D58: Video | E58: Check out our latest video on twitter! | F58: 2825 | G58: 535 | H58: 295 | I58: 45200 | J58: 44739 | K58: 169 | L58: =SUM($F58:$H58) -> 3655 | M58: #PepsiCoRefresh | N58: #PepsiCoRefresh | Q58: SummerSplash | R58: =SUM(F58:H58)/I58 -> 0.080862832
A59: P058 | B59: Instagram | C59: 45762 | D59: Reel | E59: Check out our latest reel on instagram! | F59: 103 | G59: 770 | H59: 19 | I59: 1030 | J59: 410 | K59: 262 | L59: =SUM($F59:$H59) -> 892 | M59: #PepsiCoRefresh | N59: #PepsiCoRefresh | Q59: DailyWellness | R59: =SUM(F59:H59)/I59 -> 0.86601942
A60: P059 | B60: Instagram | C60: 45465 | D60: Text | E60: Check out our latest text on instagram! | F60: 2180 | G60: 263 | H60: 387 | I60: 30520 | J60: 30059 | K60: 174 | L60: =SUM($F60:$H60) -> 2830 | M60: #ThirstyForMore | N60: #ThirstyForMore | Q60: Unassigned | R60: =SUM(F60:H60)/I60 -> 0.092726081
...

Sheet Posts_Table
A1: Post ID | B1: Platform | C1: Date | D1: Content Type | E1: Post Text | F1: Likes | G1: Shares | H1: Comments | I1: Impressions | J1: Reach | K1: Clicks | L1: Engagement | M1: Hashtags Used | N1: Campaign_Name | O1: Engagement_Rate | P1: Attribute | Q1: Hashtag
A2: P234 | B2: Facebook | C2: 45444 | D2: Text | E2: Check out our latest text on facebook! | F2: 1272 | G2: 465 | H2: 99 | I2: 24168 | J2: 23719 | K2: 42 | L2: =SUM(Table2_1[[#This Row],[Likes]:[Comments]]) -> 1836 | M2: #PepsiCoRefresh | N2: Unassigned | O2: 0.075968222 | P2: Hashtag 1 | Q2: #PepsiCoRefresh
A3: P202 | B3: Facebook | C3: 45445 | D3: Image | E3: Check out our latest image on facebook! | F3: 1871 | G3: 252 | H3: 335 | I3: 29936 | J3: 29576 | K3: 288 | L3: =SUM(Table2_1[[#This Row],[Likes]:[Comments]]) -> 2458 | M3: #ThirstyForMore | N3: NewYearRefresh | O3: 0.082108498 | P3: Hashtag 1 | Q3: #ThirstyForMore
A4: P220 | B4: Instagram | C4: 45445 | D4: Story | E4: Check out our latest story on instagram! | F4: 84 | G4: 897 | H4: 85 | I4: 588 | J4: 8 | K4: 12 | L4: =SUM(Table2_1[[#This Row],[Likes]:[Comments]]) -> 1066 | M4: #ThirstyForMore | N4: Unassigned | O4: 1.8129252 | P4: Hashtag 1 | Q4: #ThirstyForMore
A5: P090 | B5: Instagram | C5: 45446 | D5: Image | E5: Check out our latest image on instagram! | F5: 3861 | G5: 960 | H5: 101 | I5: 69498 | J5: 68817 | K5: 297 | L5: =SUM(Table2_1[[#This Row],[Likes]:[Comments]]) -> 4922 | M5: #PepsiCoRefresh | N5: DailyWellness | O5: 0.070822182 | P5: Hashtag 1 | Q5: #PepsiCoRefresh
A6: P146 | B6: YouTube | C6: 45448 | D6: Reel | E6: Check out our latest reel on youtube! | F6: 3065 | G6: 772 | H6: 142 | I6: 18390 | J6: 17875 | K6: 200 | L6: =SUM(Table2_1[[#This Row],[Likes]:[Comments]]) -> 3979 | M6: #ThirstyForMore,#AnytimeIsPepsiTime | N6: Unassigned | O6: 0.21636759 | P6: Hashtag 1 | Q6: #ThirstyForMore
A7: P146 | B7: YouTube | C7: 45448 | D7: Reel | E7: Check out our latest reel on youtube! | F7: 3065 | G7: 772 | H7: 142 | I7: 18390 | J7: 17875 | K7: 200 | L7: =SUM(Table2_1[[#This Row],[Likes]:[Comments]]) -> 3979 | M7: #ThirstyForMore,#AnytimeIsPepsiTime | N7: Unassigned | O7: 0.21636759 | P7: Hashtag 2 | Q7: #AnytimeIsPepsiTime
A8: P087 | B8: Twitter | C8: 45449 | D8: Video | E8: Check out our latest video on twitter! | F8: 1436 | G8: 765 | H8: 496 | I8: 12924 | J8: 12701 | K8: 197 | L8: =SUM(Table2_1[[#This Row],[Likes]:[Comments]]) -> 2697 | M8: #LiveForNow | N8: NewYearRefresh | O8: 0.20868152 | P8: Hashtag 1 | Q8: #LiveForNow
A9: P188 | B9: YouTube | C9: 45449 | D9: Reel | E9: Check out our latest reel on youtube! | F9: 2728 | G9: 533 | H9: 215 | I9: 40920 | J9: 40816 | K9: 137 | L9: =SUM(Table2_1[[#This Row],[Likes]:[Comments]]) -> 3476 | M9: #LiveForNow | N9: FestiveRadiance | O9: 0.084946237 | P9: Hashtag 1 | Q9: #LiveForNow
A10: P276 | B10: Twitter | C10: 45450 | D10: Carousel | E10: Check out our latest carousel on twitter! | F10: 1556 | G10: 195 | H10: 131 | I10: 9336 | J10: 8875 | K10: 137 | L10: =SUM(Table2_1[[#This Row],[Likes]:[Comments]]) -> 1882 | M10: #PepsiCoRefresh | N10: FestiveRadiance | O10: 0.20158526 | P10: Hashtag 1 | Q10: #PepsiCoRefresh
A11: P049 | B11: Twitter | C11: 45453 | D11: Story | E11: Check out our latest story on twitter! | F11: 2164 | G11: 549 | H11: 274 | I11: 28132 | J11: 27361 | K11: 177 | L11: =SUM(Table2_1[[#This Row],[Likes]:[Comments]]) -> 2987 | M11: #PepsiCoRefresh | N11: DailyWellness | O11: 0.10617802 | P11: Hashtag 1 | Q11: #PepsiCoRefresh
A12: P098 | B12: Twitter | C12: 45453 | D12: Story | E12: Check out our latest story on twitter! | F12: 1575 | G12: 771 | H12: 486 | I12: 25200 | J12: 24826 | K12: 17 | L12: =SUM(Table2_1[[#This Row],[Likes]:[Comments]]) -> 2832 | M12: #LiveForNow | N12: DailyWellness | O12: 0.11238095 | P12: Hashtag 1 | Q12: #LiveForNow
A13: P103 | B13: Facebook | C13: 45454 | D13: Image | E13: Check out our latest image on facebook! | F13: 3689 | G13: 48 | H13: 306 | I13: 40579 | J13: 39588 | K13: 212 | L13: =SUM(Table2_1[[#This Row],[Likes]:[Comments]]) -> 4043 | M13: #ThirstyForMore | N13: FestiveRadiance | O13: 0.099632815 | P13: Hashtag 1 | Q13: #ThirstyForMore
... A340: P293 | B340: Facebook | C340: 45791 | D340: Text | E340: Check out our latest text on facebook! | F340: 2634 | G340: 726 | H340: 241 | I340: 28974 | J340: 28102 | K340: 277 | L340: =SUM(Table2_1[[#This Row],[Likes]:[Comments]]) -> 3601 | M340: #ThirstyForMore | N340: SummerSplash | O340: 0.12428384 | P340: Hashtag 1 | Q340: #ThirstyForMore

Sheet Engagement Summary
A1: Week_Start_Date | B1: Platform | C1: New_Followers | D1: Unfollows | E1: Total_Followers | F1: Engagement_Rate | G1: Ad_Spend | H1: Net Growth
A2: 45446 | B2: Instagram | C2: 1135 | D2: 88 | E2: 344084 | F2: 8.06 | G2: 5904 | H2: =C2-D2 -> 1047
A3: 45446 | B3: Facebook | C3: 1312 | D3: 310 | E3: 42654 | F3: 4.98 | G3: 9566 | H3: =C3-D3 -> 1002
A4: 45446 | B4: Twitter | C4: 584 | D4: 169 | E4: 146834 | F4: 8.31 | G4: 26752 | H4: =C4-D4 -> 415
A5: 45446 | B5: YouTube | C5: 1535 | D5: 445 | E5: 395536 | F5: 4.11 | G5: 30671 | H5: =C5-D5 -> 1090
A6: 45453 | B6: Instagram | C6: 656 | D6: 139 | E6: 49157 | F6: 9.05 | G6: 9920 | H6: =C6-D6 -> 517
A7: 45453 | B7: Facebook | C7: 1697 | D7: 414 | E7: 316555 | F7: 2.37 | G7: 7924 | H7: =C7-D7 -> 1283
A8: 45453 | B8: Twitter | C8: 436 | D8: 250 | E8: 254347 | F8: 4.01 | G8: 8912 | H8: =C8-D8 -> 186
A9: 45453 | B9: YouTube | C9: 1197 | D9: 203 | E9: 413878 | F9: 3.16 | G9: 21205 | H9: =C9-D9 -> 994
A10: 45460 | B10: Instagram | C10: 1048 | D10: 155 | E10: 456946 | F10: 2.46 | G10: 11329 | H10: =C10-D10 -> 893
A11: 45460 | B11: Facebook | C11: 1753 | D11: 371 | E11: 169496 | F11: 8.11 | G11: 46670 | H11: =C11-D11 -> 1382
A12: 45460 | B12: Twitter | C12: 1335 | D12: 40 | E12: 122732 | F12: 8.19 | G12: 22482 | H12: =C12-D12 -> 1295
A13: 45460 | B13: YouTube | C13: 403 | D13: 66 | E13: 382851 | F13: 3.49 | G13: 24313 | H13: =C13-D13 -> 337
... A201: 45789 | B201: YouTube | C201: 119 | D201: 456 | E201: 82558 | F201: 6.81 | G201: 12174 | H201: =C201-D201 -> -337

Sheet Campaign Metadata
A1: Campaign_Name | B1: Start_Date | C1: End_Date | D1: Objective | E1: Total_Budget | F1: Target_Platforms | G1: Primary_Hashtags | H1: Hashtag 1 | I1: Hashtag 2 | J1: Avg_Eng_Rate_Before | K1: Avg_Eng_Rate_During | L1: Uplift % | M1: Total Engagement | N1: ROI | O1: Total Growth | P1: Avg Weekly Growth
A2: SummerSplash | B2: 45458 | C2: 45488 | D2: Brand Awareness | E2: 150000 | F2: Instagram,Facebook | G2: #ThirstyForMore,#PepsiCoRefresh | H2: #ThirstyForMore | I2: #PepsiCoRefresh | J2: =AVERAGEIFS(Posts!$R$2:$R$301,Posts!$Q$2:$Q$301,'Campaign Metadata'!$A2,Posts!$C$2:$C$301, "<" & 'Campaign Metadata'!$B2) -> 0.18256403 | K2: =AVERAGEIFS(Posts!$R$2:$R$301,Posts!$Q$2:$Q$301,'Campaign Metadata'!$A2,Posts!$C$2:$C$301, ">=" & 'Campaign Metadata'!$B2, Posts!$C$2:$C$301,"<="&'Campaign Metadata'!$C2) -> 0.077296913 | L2: =((K2-J2)/J2)*100 -> -57.660382 | M2: =SUMIF(Table1!$A$2:$A$9,'Campaign Metadata'!$A2,Table1!$K$2:$K$8) -> 95356 | N2: =M2/E2 -> 0.63570667 | O2: =SUMIFS('Engagement Summary'!$H$2:$H$201,'Engagement Summary'!$A$2:$A$201,">=" & 'Campaign Metadata'!$B2,'Engagement Summary'!$A$2:$A$201,"<=" & 'Campaign Metadata'!$C2) -> 13523 | P2: =O2/((C2-B2+1)/7) -> 3053.5806
A3: FestiveRadiance | B3: 45566 | C3: 45596 | D3: Engagement | E3: 200000 | F3: Instagram,YouTube | G3: #AnytimeIsPepsiTime, | H3: #AnytimeIsPepsiTime | J3: =AVERAGEIFS(Posts!$R$2:$R$301,Posts!$Q$2:$Q$301,'Campaign Metadata'!$A3,Posts!$C$2:$C$301, "<" & 'Campaign Metadata'!$B3) -> 0.12623972 | K3: =AVERAGEIFS(Posts!$R$2:$R$301,Posts!$Q$2:$Q$301,'Campaign Metadata'!$A3,Posts!$C$2:$C$301, ">=" & 'Campaign Metadata'!$B3, Posts!$C$2:$C$301,"<="&'Campaign Metadata'!$C3) -> 0.15063545 | L3: =((K3-J3)/J3)*100 -> 19.324926 | M3: =SUMIF(Table1!$A$2:$A$9,'Campaign Metadata'!$A3,Table1!$K$2:$K$8) -> 112836 | N3: =M3/E3 -> 0.56418 | O3: =SUMIFS('Engagement Summary'!$H$2:$H$201,'Engagement Summary'!$A$2:$A$201,">=" & 'Campaign Metadata'!$B3,'Engagement Summary'!$A$2:$A$201,"<=" & 'Campaign Metadata'!$C3) -> 11092 | P3: =O3/((C3-B3+1)/7) -> 2504.6452
A4: NewYearRefresh | B4: 45651 | C4: 45667 | D4: Product Launch | E4: 250000 | F4: Facebook,Twitter | G4: #SmoothLikeNitroPepsi | H4: #SmoothLikeNitroPepsi | J4: =AVERAGEIFS(Posts!$R$2:$R$301,Posts!$Q$2:$Q$301,'Campaign Metadata'!$A4,Posts!$C$2:$C$301, "<" & 'Campaign Metadata'!$B4) -> 0.1474176 | K4: =AVERAGEIFS(Posts!$R$2:$R$301,Posts!$Q$2:$Q$301,'Campaign Metadata'!$A4,Posts!$C$2:$C$301, ">=" & 'Campaign Metadata'!$B4, Posts!$C$2:$C$301,"<="&'Campaign Metadata'!$C4) -> 0.20610363 | L4: =((K4-J4)/J4)*100 -> 39.809376 | M4: =SUMIF(Table1!$A$2:$A$9,'Campaign Metadata'!$A4,Table1!$K$2:$K$8) -> 136746 | N4: =M4/E4 -> 0.546984 | O4: =SUMIFS('Engagement Summary'!$H$2:$H$201,'Engagement Summary'!$A$2:$A$201,">=" & 'Campaign Metadata'!$B4,'Engagement Summary'!$A$2:$A$201,"<=" & 'Campaign Metadata'!$C4) -> 10087 | P4: =O4/((C4-B4+1)/7) -> 4153.4706
A5: DailyWellness | B5: 45717 | C5: 45747 | D5: Traffic | E5: 180000 | F5: Instagram,Twitter | G5: #BetterWithPepsi,#LiveForNow | H5: #BetterWithPepsi | I5: #LiveForNow | J5: =AVERAGEIFS(Posts!$R$2:$R$301,Posts!$Q$2:$Q$301,'Campaign Metadata'!$A5,Posts!$C$2:$C$301, "<" & 'Campaign Metadata'!$B5) -> 0.13753714 | K5: =AVERAGEIFS(Posts!$R$2:$R$301,Posts!$Q$2:$Q$301,'Campaign Metadata'!$A5,Posts!$C$2:$C$301, ">=" & 'Campaign Metadata'!$B5, Posts!$C$2:$C$301,"<="&'Campaign Metadata'!$C5) -> 0.11210141 | L5: =((K5-J5)/J5)*100 -> -18.493722 | M5: =SUMIF(Table1!$A$2:$A$9,'Campaign Metadata'!$A5,Table1!$K$2:$K$8) -> 129604 | N5: =M5/E5 -> 0.72002222 | O5: =SUMIFS('Engagement Summary'!$H$2:$H$201,'Engagement Summary'!$A$2:$A$201,">=" & 'Campaign Metadata'!$B5,'Engagement Summary'!$A$2:$A$201,"<=" & 'Campaign Metadata'!$C5) -> 16078 | P5: =O5/((C5-B5+1)/7) -> 3630.5161

Sheet Table1
A1: Campaign_Name | B1: Start_Date | C1: End_Date | D1: Objective | E1: Total_Budget | F1: Primary_Hashtags | G1: Hashtag 1 | H1: Hashtag 2 | I1: Attribute | J1: Value | K1: Total Engagement
A2: SummerSplash | B2: 45458 | C2: 45488 | D2: Brand Awareness | E2: 150000 | F2: #ThirstyForMore,#PepsiCoRefresh | G2: #ThirstyForMore | H2: #PepsiCoRefresh | I2: Target_Platforms | J2: Instagram | K2: =SUMIFS(Posts!$L$2:$L$301,Posts!$Q$2:$Q$301,Table1!$A2,Posts!$B$2:$B$301,Table1!$J2) -> 55453
A3: SummerSplash | B3: 45458 | C3: 45488 | D3: Brand Awareness | E3: 150000 | F3: #ThirstyForMore,#PepsiCoRefresh | G3: #ThirstyForMore | H3: #PepsiCoRefresh | I3: Platform | J3: Facebook | K3: =SUMIFS(Posts!$L$2:$L$301,Posts!$Q$2:$Q$301,Table1!$A3,Posts!$B$2:$B$301,Table1!$J3) -> 39903
A4: FestiveRadiance | B4: 45566 | C4: 45596 | D4: Engagement | E4: 200000 | F4: #AnytimeIsPepsiTime, | G4: #AnytimeIsPepsiTime | I4: Target_Platforms | J4: Instagram | K4: =SUMIFS(Posts!$L$2:$L$301,Posts!$Q$2:$Q$301,Table1!$A4,Posts!$B$2:$B$301,Table1!$J4) -> 60551
A5: FestiveRadiance | B5: 45566 | C5: 45596 | D5: Engagement | E5: 200000 | F5: #AnytimeIsPepsiTime, | G5: #AnytimeIsPepsiTime | I5: Platform | J5: YouTube | K5: =SUMIFS(Posts!$L$2:$L$301,Posts!$Q$2:$Q$301,Table1!$A5,Posts!$B$2:$B$301,Table1!$J5) -> 52285
A6: NewYearRefresh | B6: 45651 | C6: 45667 | D6: Product Launch | E6: 250000 | F6: #SmoothLikeNitroPepsi | G6: #SmoothLikeNitroPepsi | I6: Target_Platforms | J6: Facebook | K6: =SUMIFS(Posts!$L$2:$L$301,Posts!$Q$2:$Q$301,Table1!$A6,Posts!$B$2:$B$301,Table1!$J6) -> 89114
A7: NewYearRefresh | B7: 45651 | C7: 45667 | D7: Product Launch | E7: 250000 | F7: #SmoothLikeNitroPepsi | G7: #SmoothLikeNitroPepsi | I7: Platform | J7: Twitter | K7: =SUMIFS(Posts!$L$2:$L$301,Posts!$Q$2:$Q$301,Table1!$A7,Posts!$B$2:$B$301,Table1!$J7) -> 47632
A8: DailyWellness | B8: 45717 | C8: 45747 | D8: Traffic | E8: 180000 | F8: #BetterWithPepsi,#LiveForNow | G8: #BetterWithPepsi | H8: #LiveForNow | I8: Target_Platforms | J8: Instagram | K8: =SUMIFS(Posts!$L$2:$L$301,Posts!$Q$2:$Q$301,Table1!$A8,Posts!$B$2:$B$301,Table1!$J8) -> 54374
A9: DailyWellness | B9: 45717 | C9: 45747 | D9: Traffic | E9: 180000 | F9: #BetterWithPepsi,#LiveForNow | G9: #BetterWithPepsi | H9: #LiveForNow | I9: Platform | J9: Twitter | K9: =SUMIFS(Posts!$L$2:$L$301,Posts!$Q$2:$Q$301,Table1!$A9,Posts!$B$2:$B$301,Table1!$J9) -> 75230

Sheet Task 1
A1: Task 1 | B1: Data Preprocessing and Cleaning
A3: 1. Using the Data tab and Conditional Formatting, I checked for duplicates, but none were found.
A5: 2.In the sheets Engagement Summary and Campaign Metadata, the dates were initially stored as text, so I reformatted them into proper date values using the Number group in the Home tab. I also standardized the platform names to maintain consistency.
A7: 3. Ensured that columns such as Likes, Shares, Comments, and Reach were properly formatted as numbers or currency, wherever applicable.
A9: 4. Using the Data tab, I split the data based on different hashtags and replaced the blank values in the Campaign column with 'Unassigned'.

Sheet Task 2
A1: Task 2 | B1: Engagement Analysis
A4: Question 1- To calculate the average engagement rate per platform | B4: Platform | C4: Average_Engagement_Rate | F4: Formula Used
B5: Facebook | C5: =AVERAGEIF(Posts!B2:B301,'Task 2'!B5,Posts!R2:R301) -> 0.1219729 | F5: =AVERAGEIF(Posts!B2:B301,'Task 2'!B5,Posts!Q2:Q301)
B6: Instagram | C6: =AVERAGEIF(Posts!B3:B302,'Task 2'!B6,Posts!R3:R302) -> 0.19329258
B7: Twitter | C7: =AVERAGEIF(Posts!B4:B303,'Task 2'!B7,Posts!R4:R303) -> 0.14524915
B8: YouTube | C8: =AVERAGEIF(Posts!B5:B304,'Task 2'!B8,Posts!R5:R304) -> 0.13248931
A11: Question 2- Identify top 10 posts with highest engagement. | B11: Post ID | C11: Engagement_Rate | F11: Formula Used
B12: =INDEX(Posts!$A$2:$A$301,MATCH(LARGE(Posts!$R$2:$R$301,ROW(Posts!A1)),Posts!$R$2:$R$301,0)) -> P220 | C12: =INDEX(Posts!$R$2:$R$301,MATCH('Task 2'!B12,Posts!$A$2:$A$301,0)) -> 1.8129252 | E12: Post ID | F12: =INDEX(Posts!$A$2:$A$301,MATCH(LARGE(Posts!$Q$2:$Q$301,ROW(Posts!A1)),Posts!$Q$2:$Q$301,0))
B13: =INDEX(Posts!$A$2:$A$301,MATCH(LARGE(Posts!$R$2:$R$301,ROW(Posts!A2)),Posts!$R$2:$R$301,0)) -> P058 | C13: =INDEX(Posts!$R$2:$R$301,MATCH('Task 2'!B13,Posts!$A$2:$A$301,0)) -> 0.86601942
B14: =INDEX(Posts!$A$2:$A$301,MATCH(LARGE(Posts!$R$2:$R$301,ROW(Posts!A3)),Posts!$R$2:$R$301,0)) -> P232 | C14: =INDEX(Posts!$R$2:$R$301,MATCH('Task 2'!B14,Posts!$A$2:$A$301,0)) -> 0.71686747 | E14: Engagement_Rate | F14: =INDEX(Posts!$Q$2:$Q$301,MATCH('Task 2'!B12,Posts!$A$2:$A$301,0))
B15: =INDEX(Posts!$A$2:$A$301,MATCH(LARGE(Posts!$R$2:$R$301,ROW(Posts!A4)),Posts!$R$2:$R$301,0)) -> P178 | C15: =INDEX(Posts!$R$2:$R$301,MATCH('Task 2'!B15,Posts!$A$2:$A$301,0)) -> 0.70387597
B16: =INDEX(Posts!$A$2:$A$301,MATCH(LARGE(Posts!$R$2:$R$301,ROW(Posts!A5)),Posts!$R$2:$R$301,0)) -> P175 | C16: =INDEX(Posts!$R$2:$R$301,MATCH('Task 2'!B16,Posts!$A$2:$A$301,0)) -> 0.6508216
B17: =INDEX(Posts!$A$2:$A$301,MATCH(LARGE(Posts!$R$2:$R$301,ROW(Posts!A6)),Posts!$R$2:$R$301,0)) -> P062 | C17: =INDEX(Posts!$R$2:$R$301,MATCH('Task 2'!B17,Posts!$A$2:$A$301,0)) -> 0.53773585
B18: =INDEX(Posts!$A$2:$A$301,MATCH(LARGE(Posts!$R$2:$R$301,ROW(Posts!A7)),Posts!$R$2:$R$301,0)) -> P264 | C18: =INDEX(Posts!$R$2:$R$301,MATCH('Task 2'!B18,Posts!$A$2:$A$301,0)) -> 0.53389831
B19: =INDEX(Posts!$A$2:$A$301,MATCH(LARGE(Posts!$R$2:$R$301,ROW(Posts!A8)),Posts!$R$2:$R$301,0)) -> P143 | C19: =INDEX(Posts!$R$2:$R$301,MATCH('Task 2'!B19,Posts!$A$2:$A$301,0)) -> 0.50192308
B20: =INDEX(Posts!$A$2:$A$301,MATCH(LARGE(Posts!$R$2:$R$301,ROW(Posts!A9)),Posts!$R$2:$R$301,0)) -> P210 | C20: =INDEX(Posts!$R$2:$R$301,MATCH('Task 2'!B20,Posts!$A$2:$A$301,0)) -> 0.48518408
B21: =INDEX(Posts!$A$2:$A$301,MATCH(LARGE(Posts!$R$2:$R$301,ROW(Posts!A10)),Posts!$R$2:$R$301,0)) -> P070 | C21: =INDEX(Posts!$R$2:$R$301,MATCH('Task 2'!B21,Posts!$A$2:$A$301,0)) -> 0.38274707
A24: Question 3- Create a Pivot Table
A25: a. Total Likes, Shares, and Comments by Content Type and Platform. | C25: Platforms
C26: Facebook | F26: Instagram | I26: Twitter | L26: YouTube
B27: Content Type | C27: Total Likes | D27: Total Shares | E27: Total Comments | F27: Total Likes | G27: Total Shares | H27: Total Comments | I27: Total Likes | J27: Total Shares | K27: Total Comments | L27: Total Likes | M27: Total Shares | N27: Total Comments
B28: Carousel | C28: 44476 | D28: 7400 | E28: 4589 | F28: 43948 | G28: 6975 | H28: 3890 | I28: 48649 | J28: 5791 | K28: 3607 | L28: 24926 | M28: 6305 | N28: 2422
B29: Image | C29: 71602 | D29: 12904 | E29: 6495 | F29: 34202 | G29: 5286 | H29: 2655 | I29: 43761 | J29: 7110 | K29: 5125 | L29: 23903 | M29: 4310 | N29: 2077
B30: Reel | C30: 36368 | D30: 5964 | E30: 3353 | F30: 32148 | G30: 8110 | H30: 3386 | I30: 27029 | J30: 4550 | K30: 1913 | L30: 32400 | M30: 4577 | N30: 2668
B31: Story | C31: 29405 | D31: 4950 | E31: 3223 | F31: 42649 | G31: 10049 | H31: 3846 | I31: 20466 | J31: 5090 | K31: 3026 | L31: 31968 | M31: 3866 | N31: 2012
B32: Text | C32: 31963 | D32: 4792 | E32: 3377 | F32: 25567 | G32: 5112 | H32: 1946 | I32: 31899 | J32: 4861 | K32: 3910 | L32: 27067 | M32: 3928 | N32: 1052
B33: Video | C33: 28947 | D33: 3171 | E33: 2263 | F33: 25770 | G33: 5912 | H33: 2128 | I33: 29593 | J33: 6326 | K33: 3299 | L33: 31285 | M33: 5586 | N33: 2589
B34: Grand Total | C34: 242761 | D34: 39181 | E34: 23300 | F34: 204284 | G34: 41444 | H34: 17851 | I34: 201397 | J34: 33728 | K34: 20880 | L34: 171549 | M34: 28572 | N34: 12820
A37: b.Average Clicks per post by Hashtag. | B37: Hashtags | C37: Average Clicks
A38: Here, to find Average clicks per post by Hashtag. First I need to Unpivot the Hashtag column so that different Hashtags has their respective values assigned. To do the I created Post_Table which has the respective Hashtag values. | B38: #AnytimeIsPepsiTime | C38: 161.2
B39: #BetterWithPepsi | C39: 114.85714
B40: #LiveForNow | C40: 144.03883
B41: #PepsiCoRefresh | C41: 158.65421
B42: #SmoothLikeNitroPepsi | C42: 111.8
B43: #ThirstyForMore | C43: 151.52941
B44: Grand Total | C44: 150.58702
A47: Question 4- Highlight top-performing hashtags using a formula-based ranking. | B47: =B37 -> Hashtags | C47: =C37 -> Average Clicks | D47: Rank | G47: Formula Used
B48: =B38 -> #AnytimeIsPepsiTime | C48: =C38 -> 161.2 | D48: =_xlfn.RANK.EQ(C48,$C$48:$C$53,0) -> 1 | G48: =RANK.EQ(C48,$C$48:$C$53,0)
B49: =B39 -> #BetterWithPepsi | C49: =C39 -> 114.85714 | D49: =_xlfn.RANK.EQ(C49,$C$48:$C$53,0) -> 5
A50: Used conditional formatting for highlighting the top 3 performing hashtag. | B50: =B40 -> #LiveForNow | C50: =C40 -> 144.03883 | D50: =_xlfn.RANK.EQ(C50,$C$48:$C$53,0) -> 4
...

Sheet Task 3
A1: Task 3 | B1: Social Media Platform analysis
A4: Question 1- Identify which Platform generates the highest engagement. | C4: Platform | D4: Total Engagement | E4: Average Engagement_Rate
C5: Facebook | D5: 305242 | E5: 0.1219729
C6: Instagram | D6: 263579 | E6: 0.19329258
C7: Twitter | D7: 256005 | E7: 0.14368407
C8: YouTube | D8: 212941 | E8: 0.13118494
C9: Grand Total | D9: 1037767 | E9: 0.14828272
A13: Question 2- Compare Growth rates of followers across different platforms. | C13: start_week | D13: end_week | F13: Growth Rate | K13: Formula Used | L13: =(end_follower-start_follower)/start_follower
C14: 45446 | D14: 45789 | F14: platform | G14: start_follower | H14: end_follower | I14: growth rate
F15: Instagram | G15: 344084 | H15: 468301 | I15: =(H15-G15)/G15 -> 0.36100778
F16: Facebook | G16: 42654 | H16: 364820 | I16: =(H16-G16)/G16 -> 7.5530079
F17: Twitter | G17: 146834 | H17: 456298 | I17: =(H17-G17)/G17 -> 2.1075773
F18: YouTube | G18: 395536 | H18: 82558 | I18: =(H18-G18)/G18 -> -0.79127564
A32: Question 3- Visualize the engagement by ad spend across Platform. | C32: Platform | D32: Total_Engagement | E32: Total_Ad_Spend | F32: Engagement_per_Rupee | H32: Formula Used
C33: Facebook | D33: 305242 | E33: 1379539 | F33: =D33/E33 -> 0.22126377 | H33: =Total_Engagement/Total_Ad_Spend
C34: Instagram | D34: 263579 | E34: 1164373 | F34: =D34/E34 -> 0.2263699
C35: Twitter | D35: 256005 | E35: 1060357 | F35: =D35/E35 -> 0.24143284
C36: YouTube | D36: 212941 | E36: 1228647 | F36: =D36/E36 -> 0.17331341
A58: QUESTION 4- Advise whether to focus on 1–2 core platforms or continue multi-platform strategy. Justify the opinion by the analysis.

Sheet Task 4
A1: Task 4 | B1: Hashtag & Content Strategy
A2: Question 1 - a) Most frequently used hashtags. | C2: Hashtags | D2: Times Used
C3: #AnytimeIsPepsiTime | D3: 15
C4: #BetterWithPepsi | D4: 7
C5: #LiveForNow | D5: 103
C6: #PepsiCoRefresh | D6: 107
C7: #SmoothLikeNitroPepsi | D7: 5
C8: #ThirstyForMore | D8: 102
C9: Grand Total | D9: 339
A12: Question 1 - b) Average performance (likes, comments) of posts containing each hashtag.
C13: Hashtags | D13: Average Likes | E13: Average Comments | F13: Average Shares | G13: Average Clicks
C14: #AnytimeIsPepsiTime | D14: 2219.6 | E14: 257.4 | F14: 423.93333 | G14: 161.2
C15: #BetterWithPepsi | D15: 3451.7143 | E15: 151 | F15: 540.57143 | G15: 114.85714
C16: #LiveForNow | D16: 2634.7184 | E16: 262.50485 | F16: 508.63107 | G16: 144.03883
C17: #PepsiCoRefresh | D17: 2705.1028 | E17: 254.18692 | F17: 458.01869 | G17: 158.65421
C18: #SmoothLikeNitroPepsi | D18: 3127.8 | E18: 283.4 | F18: 356.2 | G18: 111.8
C19: #ThirstyForMore | D19: 2838.8039 | E19: 230.95098 | F19: 464.96078 | G19: 151.52941
C20: Grand Total | D20: 2724.115 | E20: 248.16519 | F20: 474.17994 | G20: 150.58702
C22: In terms of Avg of Likes and Shares, #BetterWithPepsi has performed better than some of the most frequently used Hashtags.
A26: Question 2- Compare performance of videos vs. images vs. carousels across platforms. | C26: Average Engagement_Rate | D26: Platform
C27: Content Type | D27: Facebook | E27: Instagram | F27: Twitter | G27: YouTube
C28: Carousel | D28: 0.1182059 | E28: 0.14358583 | F28: 0.14537055 | G28: 0.19045606
C29: Image | D29: 0.11745425 | E29: 0.13475594 | F29: 0.14530583 | G29: 0.15035568
C30: Video | D30: 0.12378368 | E30: 0.20035942 | F30: 0.11228207 | G30: 0.12194863
A33: Question 3- Recommend which content types should be prioritized on which platform.

Sheet Task 5
A1: Task 5 | B1: Campaign Effectiveness
A4: Question 1- a) Total and average impressions, likes, and clicks per campaign. | C4: Campaign_Name | D4: Total Impressions | E4: Average Impressions | F4: Total Likes | G4: Average Likes | H4: Total Clicks | I4: Average Clicks
C5: DailyWellness | D5: 2464864 | E5: 34716.394 | F5: 187909 | G5: 2646.6056 | H5: 10689 | I5: 150.5493
C6: FestiveRadiance | D6: 1986356 | E6: 34247.517 | F6: 159783 | G6: 2754.8793 | H6: 9872 | I6: 170.2069
C7: NewYearRefresh | D7: 2266053 | E7: 33821.687 | F7: 183346 | G7: 2736.5075 | H7: 10032 | I7: 149.73134
C8: SummerSplash | D8: 1846272 | E8: 38464 | F8: 138793 | G8: 2891.5208 | H8: 6434 | I8: 134.04167
C9: Grand Total | D9: 8563545 | E9: 35096.496 | F9: 669831 | G9: 2745.209 | H9: 37027 | I9: 151.75
A14: Question 2- b) Engagement uplift during vs. before the campaign period. | C14: Campaign_Name | D14: Avg_Eng_Rate_Before | E14: Avg_Eng_Rate_During | F14: Uplift % | I14: Formula Used
C15: SummerSplash | D15: 0.18256403 | E15: 0.077296913 | F15: -57.660382 | G15: Avg_Eng_Rate_Before | I15: =AVERAGEIFS(Posts!$R$2:$R$301,Posts!$Q$2:$Q$301,'Campaign Metadata'!$A2,Posts!$C$2:$C$301, "<" & 'Campaign Metadata'!$B2)
C16: FestiveRadiance | D16: 0.12623972 | E16: 0.15063545 | F16: 19.324926 | G16: Avg_Eng_Rate_During | I16: =AVERAGEIFS(Posts!$R$2:$R$301,Posts!$Q$2:$Q$301,'Campaign Metadata'!$A2,Posts!$C$2:$C$301, ">=" & 'Campaign Metadata'!$B2, Posts!$C$2:$C$301,"<="&'Campaign Metadata'!$C2)
C17: NewYearRefresh | D17: 0.1474176 | E17: 0.20610363 | F17: 39.809376
C18: DailyWellness | D18: 0.13753714 | E18: 0.11210141 | F18: -18.493722 | G18: Uplift % | I18: =((Avg_Eng_Rate_During-Avg_Eng_Rate_Before)/Avg_Eng_Rate_Before)*100
A23: Question 2- a) Which campaign had the highest ROI in terms of engagement vs. budget.
C24: Campaign_Name | D24: ROI | F24: Formula Used
C25: SummerSplash | D25: 0.63570667 | F25: ROI = Total_Engagement/Total_Budget
C26: FestiveRadiance | D26: 0.56418
C27: NewYearRefresh | D27: 0.546984
C28: DailyWellness | D28: 0.72002222
A32: Question 2- b) Which campaign had the strongest follower growth impact. | C32: Campaign_Name | D32: Total Net Growth | E32: Avg Weekly Growth
C33: SummerSplash | D33: 13523 | E33: 3053.5806
C34: FestiveRadiance | D34: 11092 | E34: 2504.6452
C35: NewYearRefresh | D35: 10087 | E35: 4153.4706
C36: DailyWellness | D36: 16078 | E36: 3630.5161

Sheet Task 6
A1: Task 6 | B1: Follower Retention & Audience Loyalty
A4: Question 1- Visualize weekly follower growth trends by platform using line charts. | C4: Net Growth Per Platform | D4: Platform
C5: Weekdates | D5: Facebook | E5: Instagram | F5: Twitter | G5: YouTube
C6: 45446 | D6: 1002 | E6: 1047 | F6: 415 | G6: 1090
C7: 45453 | D7: 1283 | E7: 517 | F7: 186 | G7: 994
C8: 45460 | D8: 1382 | E8: 893 | F8: 1295 | G8: 337
C9: 45467 | D9: 1670 | E9: 629 | F9: 835 | G9: -123
C10: 45474 | D10: 64 | E10: -219 | F10: 1357 | G10: 91
C11: 45481 | D11: 309 | E11: 1672 | F11: 547 | G11: 514
C12: 45488 | D12: -164 | E12: 1845 | F12: 429 | G12: 160
C13: 45495 | D13: 961 | E13: 159 | F13: 1316 | G13: 317
C14: 45502 | D14: -318 | E14: 541 | F14: 1495 | G14: 475
C15: 45509 | D15: -197 | E15: 352 | F15: 328 | G15: 319
C16: 45516 | D16: 1334 | E16: 1325 | F16: 37 | G16: 1032
C17: 45523 | D17: 1058 | E17: 76 | F17: 1665 | G17: 190
... C55: 45789 | D55: 407 | E55: 1656 | F55: 269 | G55: -337
A60: Question 2- Identify the week with the highest net follower gain. | C60: Max Net Follower | D60: Weekday
C61: =MAX('Engagement Summary'!H2:H201) -> 1881 | D61: =INDEX('Engagement Summary'!A2:A201,MATCH(MAX('Engagement Summary'!H2:H201),'Engagement Summary'!H2:H201,0)) -> 45782
C63: Formula Used
C65: Max Net Follower | D65: =MAX('Engagement Summary'!H2:H201)
C66: Weekday | D66: =INDEX('Engagement Summary'!A2:A201,MATCH(MAX('Engagement Summary'!H2:H201),'Engagement Summary'!H2:H201,0))
A68: Question 3- Create a moving average chart to smooth out follower growth trends. | C68: Sum of Net Growth | D68: Platform
C69: Row Labels | D69: Facebook | E69: Instagram | F69: Twitter | G69: YouTube | H69: Facebook MA | I69: Instagram MA | J69: Twitter MA | K69: YouTube MA
C70: 45446 | D70: 1002 | E70: 1047 | F70: 415 | G70: 1090
C71: 45453 | D71: 1283 | E71: 517 | F71: 186 | G71: 994
C72: 45460 | D72: 1382 | E72: 893 | F72: 1295 | G72: 337
C73: 45467 | D73: 1670 | E73: 629 | F73: 835 | G73: -123 | H73: =AVERAGE(D70:D73) -> 1334.25 | I73: =AVERAGE(E70:E73) -> 771.5 | J73: =AVERAGE(F70:F73) -> 682.75 | K73: =AVERAGE(G70:G73) -> 574.5
C74: 45474 | D74: 64 | E74: -219 | F74: 1357 | G74: 91 | H74: =AVERAGE(D71:D74) -> 1099.75 | I74: =AVERAGE(E71:E74) -> 455 | J74: =AVERAGE(F71:F74) -> 918.25 | K74: =AVERAGE(G71:G74) -> 324.75
C75: 45481 | D75: 309 | E75: 1672 | F75: 547 | G75: 514 | H75: =AVERAGE(D72:D75) -> 856.25 | I75: =AVERAGE(E72:E75) -> 743.75 | J75: =AVERAGE(F72:F75) -> 1008.5 | K75: =AVERAGE(G72:G75) -> 204.75
C76: 45488 | D76: -164 | E76: 1845 | F76: 429 | G76: 160 | H76: =AVERAGE(D73:D76) -> 469.75 | I76: =AVERAGE(E73:E76) -> 981.75 | J76: =AVERAGE(F73:F76) -> 792 | K76: =AVERAGE(G73:G76) -> 160.5
C77: 45495 | D77: 961 | E77: 159 | F77: 1316 | G77: 317 | H77: =AVERAGE(D74:D77) -> 292.5 | I77: =AVERAGE(E74:E77) -> 864.25 | J77: =AVERAGE(F74:F77) -> 912.25 | K77: =AVERAGE(G74:G77) -> 270.5
C78: 45502 | D78: -318 | E78: 541 | F78: 1495 | G78: 475 | H78: =AVERAGE(D75:D78) -> 197 | I78: =AVERAGE(E75:E78) -> 1054.25 | J78: =AVERAGE(F75:F78) -> 946.75 | K78: =AVERAGE(G75:G78) -> 366.5
C79: 45509 | D79: -197 | E79: 352 | F79: 328 | G79: 319 | H79: =AVERAGE(D76:D79) -> 70.5 | I79: =AVERAGE(E76:E79) -> 724.25 | J79: =AVERAGE(F76:F79) -> 892 | K79: =AVERAGE(G76:G79) -> 317.75
C80: 45516 | D80: 1334 | E80: 1325 | F80: 37 | G80: 1032 | H80: =AVERAGE(D77:D80) -> 445 | I80: =AVERAGE(E77:E80) -> 594.25 | J80: =AVERAGE(F77:F80) -> 794 | K80: =AVERAGE(G77:G80) -> 535.75
C81: 45523 | D81: 1058 | E81: 76 | F81: 1665 | G81: 190 | H81: =AVERAGE(D78:D81) -> 469.25 | I81: =AVERAGE(E78:E81) -> 573.5 | J81: =AVERAGE(F78:F81) -> 881.25 | K81: =AVERAGE(G78:G81) -> 504
C82: 45530 | D82: 37 | E82: 1609 | F82: 1229 | G82: 28 | H82: =AVERAGE(D79:D82) -> 558 | I82: =AVERAGE(E79:E82) -> 840.5 | J82: =AVERAGE(F79:F82) -> 814.75 | K82: =AVERAGE(G79:G82) -> 392.25
C83: 45537 | D83: 1045 | E83: 1247 | F83: 197 | G83: 333 | H83: =AVERAGE(D80:D83) -> 868.5 | I83: =AVERAGE(E80:E83) -> 1064.25 | J83: =AVERAGE(F80:F83) -> 782 | K83: =AVERAGE(G80:G83) -> 395.75
C84: 45544 | D84: 1428 | E84: 1572 | F84: 260 | G84: 1100 | H84: =AVERAGE(D81:D84) -> 892 | I84: =AVERAGE(E81:E84) -> 1126 | J84: =AVERAGE(F81:F84) -> 837.75 | K84: =AVERAGE(G81:G84) -> 412.75
... C119: 45789 | D119: 407 | E119: 1656 | F119: 269 | G119: -337 | H119: =AVERAGE(D116:D119) -> 561 | I119: =AVERAGE(E116:E119) -> 1419.75 | J119: =AVERAGE(F116:F119) -> 871.5 | K119: =AVERAGE(G116:G119) -> 699.25
A122: Question 4- Determine the correlation between ad spend and follower growth using scatter plots and basic correlation calculation.
...
